[ERROR] 2019-01-14 19:08:04,443 >>	Unexpected Exception Occurred.
Traceback (most recent call last):
  File "src/main.py", line 20, in <module>
    main(get_option())
  File "src/main.py", line 12, in main
    ProcessorFactory.process(args)
  File "/Users/berry/Kaggle/malware/src/processor_factory.py", line 33, in process
    dataset_path = cls.ROOT_PATH / params["DatasetPath"]
KeyError: 'DatasetPath'
