[INFO] 2019-01-06 15:23:19,287 >>	[START]  Processor.process_train()
[INFO] 2019-01-06 15:23:19,287 >>	[START]  FeatureExtractor.extract()
[INFO] 2019-01-06 15:23:19,637 >>	[FINISH] FeatureExtractor.extract(): [elapsed_time] >> 00:00:00
[INFO] 2019-01-06 15:23:19,638 >>	[START]  MocoClassifier.fit()
[ERROR] 2019-01-06 15:23:19,661 >>	Unexpected Exception Occurred.
Traceback (most recent call last):
  File "/Users/berry/.pyenv/versions/anaconda3-5.3.1/lib/python3.7/site-packages/pandas/core/indexes/base.py", line 3078, in get_loc
    return self._engine.get_loc(key)
  File "pandas/_libs/index.pyx", line 140, in pandas._libs.index.IndexEngine.get_loc
  File "pandas/_libs/index.pyx", line 162, in pandas._libs.index.IndexEngine.get_loc
  File "pandas/_libs/hashtable_class_helper.pxi", line 1492, in pandas._libs.hashtable.PyObjectHashTable.get_item
  File "pandas/_libs/hashtable_class_helper.pxi", line 1500, in pandas._libs.hashtable.PyObjectHashTable.get_item
KeyError: 'HasDetections'

During handling of the above exception, another exception occurred:

Traceback (most recent call last):
  File "src/main.py", line 18, in <module>
    main(get_option())
  File "src/main.py", line 10, in main
    ProcessorFactory.process(args)
  File "/Users/berry/Kaggle/malware/src/processor_factory.py", line 32, in process
    validity, predict = processor.process()
  File "/Users/berry/Kaggle/malware/src/processor.py", line 26, in process
    validity = self.__process_train()
  File "/Users/berry/Kaggle/malware/src/save_log.py", line 80, in wrapper
    result = func(*args, **kargs)
  File "/Users/berry/Kaggle/malware/src/processor.py", line 43, in __process_train
    self.classifier.fit(df)
  File "/Users/berry/Kaggle/malware/src/save_log.py", line 80, in wrapper
    result = func(*args, **kargs)
  File "/Users/berry/Kaggle/malware/src/moco_classifier.py", line 13, in fit
    clfs = self.__fit_as_classifier_type(train_df)
  File "/Users/berry/Kaggle/malware/src/moco_classifier.py", line 27, in __fit_as_classifier_type
    return self.__fit_with_lgbm(df)
  File "/Users/berry/Kaggle/malware/src/moco_classifier.py", line 36, in __fit_with_lgbm
    del df["MachineIdentifier"], df["HasDetections"]
  File "/Users/berry/.pyenv/versions/anaconda3-5.3.1/lib/python3.7/site-packages/pandas/core/generic.py", line 2743, in __delitem__
    self._data.delete(key)
  File "/Users/berry/.pyenv/versions/anaconda3-5.3.1/lib/python3.7/site-packages/pandas/core/internals.py", line 4174, in delete
    indexer = self.items.get_loc(item)
  File "/Users/berry/.pyenv/versions/anaconda3-5.3.1/lib/python3.7/site-packages/pandas/core/indexes/base.py", line 3080, in get_loc
    return self._engine.get_loc(self._maybe_cast_indexer(key))
  File "pandas/_libs/index.pyx", line 140, in pandas._libs.index.IndexEngine.get_loc
  File "pandas/_libs/index.pyx", line 162, in pandas._libs.index.IndexEngine.get_loc
  File "pandas/_libs/hashtable_class_helper.pxi", line 1492, in pandas._libs.hashtable.PyObjectHashTable.get_item
  File "pandas/_libs/hashtable_class_helper.pxi", line 1500, in pandas._libs.hashtable.PyObjectHashTable.get_item
KeyError: 'HasDetections'
