[INFO] 2019-01-06 18:09:21,566 >>	[START]  Processor.process_train()
[INFO] 2019-01-06 18:09:21,566 >>	[START]  FeatureExtractor.extract()
[INFO] 2019-01-06 18:09:21,734 >>	[FINISH] FeatureExtractor.extract(): [elapsed_time] >> 00:00:00
[INFO] 2019-01-06 18:09:21,735 >>	[START]  MocoClassifier.fit()
[ERROR] 2019-01-06 18:09:21,742 >>	Unexpected Exception Occurred.
Traceback (most recent call last):
  File "src/main.py", line 18, in <module>
    main(get_option())
  File "src/main.py", line 10, in main
    ProcessorFactory.process(args)
  File "/Users/berry/Kaggle/malware/src/processor_factory.py", line 32, in process
    validity, predict = processor.process()
  File "/Users/berry/Kaggle/malware/src/processor.py", line 26, in process
    validity = self.__process_train()
  File "/Users/berry/Kaggle/malware/src/save_log.py", line 80, in wrapper
    result = func(*args, **kargs)
  File "/Users/berry/Kaggle/malware/src/processor.py", line 43, in __process_train
    self.classifier.fit(df)
  File "/Users/berry/Kaggle/malware/src/save_log.py", line 80, in wrapper
    result = func(*args, **kargs)
  File "/Users/berry/Kaggle/malware/src/moco_classifier.py", line 18, in fit
    clfs = self.__fit_as_classifier_type(train_df)
  File "/Users/berry/Kaggle/malware/src/moco_classifier.py", line 32, in __fit_as_classifier_type
    return self.__fit_with_lgbm(df)
  File "/Users/berry/Kaggle/malware/src/moco_classifier.py", line 73, in __fit_with_lgbm
    early_stopping_rounds=mtd_params["early_stopping_rounds"])
  File "/Users/berry/.pyenv/versions/anaconda3-5.3.1/lib/python3.7/site-packages/lightgbm/engine.py", line 195, in train
    booster = Booster(params=params, train_set=train_set)
  File "/Users/berry/.pyenv/versions/anaconda3-5.3.1/lib/python3.7/site-packages/lightgbm/basic.py", line 1510, in __init__
    train_set.construct().handle,
  File "/Users/berry/.pyenv/versions/anaconda3-5.3.1/lib/python3.7/site-packages/lightgbm/basic.py", line 987, in construct
    categorical_feature=self.categorical_feature, params=self.params)
  File "/Users/berry/.pyenv/versions/anaconda3-5.3.1/lib/python3.7/site-packages/lightgbm/basic.py", line 719, in _lazy_init
    self.pandas_categorical)
  File "/Users/berry/.pyenv/versions/anaconda3-5.3.1/lib/python3.7/site-packages/lightgbm/basic.py", line 277, in _data_from_pandas
    raise ValueError(msg + ', '.join(bad_fields))
ValueError: DataFrame.dtypes for data must be int, float or bool.
Did not expect the data types in fields ProductName_plain, EngineVersion_plain, AppVersion_plain, AvSigVersion_plain, Platform_plain, OsBuildLab_plain, Census_MDC2FormFactor_plain, Census_OSVersion_plain
