[INFO] 2019-01-13 02:03:35,253 >>	[START]  Processor.preprocess()
[INFO] 2019-01-13 02:03:35,254 >>	[START]  FeatureExtractor.extract()
[INFO] 2019-01-13 02:03:35,264 >>	[FINISH] FeatureExtractor.extract(): [elapsed_time] >> 00:00:00
[INFO] 2019-01-13 02:03:35,265 >>	[START]  FeatureExtractor.extract()
[INFO] 2019-01-13 02:03:35,270 >>	[FINISH] FeatureExtractor.extract(): [elapsed_time] >> 00:00:00
[INFO] 2019-01-13 02:03:35,271 >>	[START]  FeatureExtractor.extract()
[INFO] 2019-01-13 02:03:35,277 >>	[FINISH] FeatureExtractor.extract(): [elapsed_time] >> 00:00:00
[INFO] 2019-01-13 02:03:35,277 >>	[START]  FeatureExtractor.extract()
[INFO] 2019-01-13 02:03:35,283 >>	[FINISH] FeatureExtractor.extract(): [elapsed_time] >> 00:00:00
[INFO] 2019-01-13 02:03:35,284 >>	[START]  FeatureExtractor.extract()
[INFO] 2019-01-13 02:03:35,292 >>	[FINISH] FeatureExtractor.extract(): [elapsed_time] >> 00:00:00
[INFO] 2019-01-13 02:03:35,292 >>	[START]  FeatureExtractor.extract()
[INFO] 2019-01-13 02:03:35,299 >>	[FINISH] FeatureExtractor.extract(): [elapsed_time] >> 00:00:00
[INFO] 2019-01-13 02:03:35,300 >>	[START]  FeatureExtractor.extract()
[INFO] 2019-01-13 02:03:35,305 >>	[FINISH] FeatureExtractor.extract(): [elapsed_time] >> 00:00:00
[INFO] 2019-01-13 02:03:35,306 >>	[START]  FeatureExtractor.extract()
[INFO] 2019-01-13 02:03:35,311 >>	[FINISH] FeatureExtractor.extract(): [elapsed_time] >> 00:00:00
[INFO] 2019-01-13 02:03:35,312 >>	[START]  FeatureExtractor.extract()
[INFO] 2019-01-13 02:03:35,317 >>	[FINISH] FeatureExtractor.extract(): [elapsed_time] >> 00:00:00
[INFO] 2019-01-13 02:03:35,318 >>	[START]  FeatureExtractor.extract()
[INFO] 2019-01-13 02:03:35,323 >>	[FINISH] FeatureExtractor.extract(): [elapsed_time] >> 00:00:00
[INFO] 2019-01-13 02:03:35,324 >>	[FINISH] Processor.preprocess(): [elapsed_time] >> 00:00:00
[INFO] 2019-01-13 02:03:35,324 >>	[START]  Processor.train()
[INFO] 2019-01-13 02:03:35,324 >>	[START]  MocoClassifier.train()
[INFO] 2019-01-13 02:03:35,326 >>		 >> 0 folds start
[ERROR] 2019-01-13 02:03:35,427 >>	Unexpected Exception Occurred.
Traceback (most recent call last):
  File "/Users/berry/.pyenv/versions/anaconda3-5.3.1/lib/python3.7/site-packages/pandas/core/indexes/base.py", line 3078, in get_loc
    return self._engine.get_loc(key)
  File "pandas/_libs/index.pyx", line 140, in pandas._libs.index.IndexEngine.get_loc
  File "pandas/_libs/index.pyx", line 162, in pandas._libs.index.IndexEngine.get_loc
  File "pandas/_libs/hashtable_class_helper.pxi", line 1492, in pandas._libs.hashtable.PyObjectHashTable.get_item
  File "pandas/_libs/hashtable_class_helper.pxi", line 1500, in pandas._libs.hashtable.PyObjectHashTable.get_item
KeyError: 'HasDetections'

During handling of the above exception, another exception occurred:

Traceback (most recent call last):
  File "src/main.py", line 20, in <module>
    main(get_option())
  File "src/main.py", line 12, in main
    ProcessorFactory.process(args)
  File "/Users/berry/Kaggle/malware/src/processor_factory.py", line 32, in process
    validity, predict = processor.process()
  File "/Users/berry/Kaggle/malware/src/processor.py", line 30, in process
    validity = self.__train(feature_names)
  File "/Users/berry/Kaggle/malware/src/save_log.py", line 83, in wrapper
    result = func(*args, **kargs)
  File "/Users/berry/Kaggle/malware/src/processor.py", line 59, in __train
    self.classifier.train(feature_names)
  File "/Users/berry/Kaggle/malware/src/save_log.py", line 83, in wrapper
    result = func(*args, **kargs)
  File "/Users/berry/Kaggle/malware/src/moco_classifier.py", line 22, in train
    clfs = self.__train_as_classifier_type(train_df)
  File "/Users/berry/Kaggle/malware/src/moco_classifier.py", line 57, in __train_as_classifier_type
    return self.__train_with_lgbm(feature_names)
  File "/Users/berry/Kaggle/malware/src/moco_classifier.py", line 84, in __train_with_lgbm
    trn_y = trn_x["HasDetections"].astype(np.int8)
  File "/Users/berry/.pyenv/versions/anaconda3-5.3.1/lib/python3.7/site-packages/pandas/core/frame.py", line 2688, in __getitem__
    return self._getitem_column(key)
  File "/Users/berry/.pyenv/versions/anaconda3-5.3.1/lib/python3.7/site-packages/pandas/core/frame.py", line 2695, in _getitem_column
    return self._get_item_cache(key)
  File "/Users/berry/.pyenv/versions/anaconda3-5.3.1/lib/python3.7/site-packages/pandas/core/generic.py", line 2489, in _get_item_cache
    values = self._data.get(item)
  File "/Users/berry/.pyenv/versions/anaconda3-5.3.1/lib/python3.7/site-packages/pandas/core/internals.py", line 4115, in get
    loc = self.items.get_loc(item)
  File "/Users/berry/.pyenv/versions/anaconda3-5.3.1/lib/python3.7/site-packages/pandas/core/indexes/base.py", line 3080, in get_loc
    return self._engine.get_loc(self._maybe_cast_indexer(key))
  File "pandas/_libs/index.pyx", line 140, in pandas._libs.index.IndexEngine.get_loc
  File "pandas/_libs/index.pyx", line 162, in pandas._libs.index.IndexEngine.get_loc
  File "pandas/_libs/hashtable_class_helper.pxi", line 1492, in pandas._libs.hashtable.PyObjectHashTable.get_item
  File "pandas/_libs/hashtable_class_helper.pxi", line 1500, in pandas._libs.hashtable.PyObjectHashTable.get_item
KeyError: 'HasDetections'
