[INFO] 2019-01-05 22:43:27,388 >>	[START]  Processor.process_train()
[INFO] 2019-01-05 22:43:27,388 >>	[START]  FeatureExtractor.extract()
[INFO] 2019-01-05 22:43:27,566 >>	[FINISH] FeatureExtractor.extract(): [elapsed_time] >> 00:00:00
[ERROR] 2019-01-05 22:43:27,610 >>	Unexpected Exception Occurred.
Traceback (most recent call last):
  File "src/main.py", line 18, in <module>
    main(get_option())
  File "src/main.py", line 10, in main
    ProcessorFactory.process(args)
  File "/Users/icebee/Project/malware/src/processor_factory.py", line 32, in process
    validity, predict = processor.process()
  File "/Users/icebee/Project/malware/src/processor.py", line 26, in process
    validity = self.__process_train()
  File "/Users/icebee/Project/malware/src/save_log.py", line 80, in wrapper
    result = func(*args, **kargs)
  File "/Users/icebee/Project/malware/src/processor.py", line 44, in __process_train
    assert False
AssertionError
