[INFO] 2019-02-16 23:26:41,796 >>	Classifier Type: PYTORCH
[INFO] 2019-02-16 23:26:41,797 >>	Input Path: /media/mocobt/Volume/Kaggle/Malware/data/subset/min
[INFO] 2019-02-16 23:26:41,797 >>	--------------------------------
[INFO] 2019-02-16 23:26:41,798 >>	[START]  Processor.preprocess()
[INFO] 2019-02-16 23:26:41,799 >>	[START]  FeatureExtractor.extract()
[INFO] 2019-02-16 23:26:41,814 >>	[FINISH] FeatureExtractor.extract(): [elapsed_time] >> 00:00:00
[INFO] 2019-02-16 23:26:41,815 >>	[START]  FeatureExtractor.extract()
[INFO] 2019-02-16 23:26:41,817 >>	[FINISH] FeatureExtractor.extract(): [elapsed_time] >> 00:00:00
[INFO] 2019-02-16 23:26:41,819 >>	[START]  FeatureExtractor.extract()
[INFO] 2019-02-16 23:26:41,821 >>	[FINISH] FeatureExtractor.extract(): [elapsed_time] >> 00:00:00
[INFO] 2019-02-16 23:26:41,822 >>	[START]  FeatureExtractor.extract()
[INFO] 2019-02-16 23:26:41,826 >>	[FINISH] FeatureExtractor.extract(): [elapsed_time] >> 00:00:00
[INFO] 2019-02-16 23:26:41,828 >>	[START]  FeatureExtractor.extract()
[INFO] 2019-02-16 23:26:41,831 >>	[FINISH] FeatureExtractor.extract(): [elapsed_time] >> 00:00:00
[INFO] 2019-02-16 23:26:41,832 >>	[START]  FeatureExtractor.extract()
[INFO] 2019-02-16 23:26:41,834 >>	[FINISH] FeatureExtractor.extract(): [elapsed_time] >> 00:00:00
[INFO] 2019-02-16 23:26:41,837 >>	[START]  FeatureExtractor.extract()
[INFO] 2019-02-16 23:26:41,841 >>	[FINISH] FeatureExtractor.extract(): [elapsed_time] >> 00:00:00
[INFO] 2019-02-16 23:26:41,842 >>	[START]  FeatureExtractor.extract()
[INFO] 2019-02-16 23:26:41,845 >>	[FINISH] FeatureExtractor.extract(): [elapsed_time] >> 00:00:00
[INFO] 2019-02-16 23:26:41,846 >>	[START]  FeatureExtractor.extract()
[INFO] 2019-02-16 23:26:41,850 >>	[FINISH] FeatureExtractor.extract(): [elapsed_time] >> 00:00:00
[INFO] 2019-02-16 23:26:41,851 >>	[START]  FeatureExtractor.extract()
[INFO] 2019-02-16 23:26:41,854 >>	[FINISH] FeatureExtractor.extract(): [elapsed_time] >> 00:00:00
[INFO] 2019-02-16 23:26:41,855 >>	[FINISH] Processor.preprocess(): [elapsed_time] >> 00:00:00
[INFO] 2019-02-16 23:26:41,856 >>	[START]  Processor.train()
[INFO] 2019-02-16 23:26:41,857 >>	[START]  PyTorchClassifier.train()
[INFO] 2019-02-16 23:26:41,859 >>		 >> 0 folds start
[INFO] 2019-02-16 23:26:41,860 >>		 	 Generating datasets...
[INFO] 2019-02-16 23:26:41,862 >>		 	 	 Reading train_Kernel02.csv...
[INFO] 2019-02-16 23:26:41,869 >>		 	 	 Reading train_Binary.csv...
[INFO] 2019-02-16 23:26:51,514 >>		 	 	 Reading validate_Kernel02.csv...
[INFO] 2019-02-16 23:26:51,518 >>		 	 	 Reading validate_Binary.csv...
[INFO] 2019-02-16 23:27:00,938 >>		 	 Datasets were generated.
[ERROR] 2019-02-16 23:27:02,460 >>	Unexpected Exception Occurred.
Traceback (most recent call last):
  File "src/main.py", line 23, in <module>
    main(get_option())
  File "src/main.py", line 14, in main
    ProcessorFactory.process(args)
  File "/media/mocobt/Volume/Kaggle/Malware/src/processor_factory.py", line 39, in process
    validity, predict = processor.process()
  File "/media/mocobt/Volume/Kaggle/Malware/src/processor.py", line 42, in process
    validity = None if only_prediction() and model_exist() else self.__train(feature_names)
  File "/media/mocobt/Volume/Kaggle/Malware/src/save_log.py", line 112, in wrapper
    result = func(*args, **kargs)
  File "/media/mocobt/Volume/Kaggle/Malware/src/processor.py", line 69, in __train
    return self.classifier.train(feature_names)
  File "/media/mocobt/Volume/Kaggle/Malware/src/save_log.py", line 112, in wrapper
    result = func(*args, **kargs)
  File "/media/mocobt/Volume/Kaggle/Malware/src/classifier/pytorch_classifier.py", line 86, in train
    early_stopping_rounds=early_stopping_rounds)
  File "/media/mocobt/Volume/Kaggle/Malware/src/classifier/torch_util.py", line 74, in train_model
    loss = criterion(outputs, labels)
  File "/home/mocobt/.pyenv/versions/anaconda3-5.3.1/lib/python3.7/site-packages/torch/nn/modules/module.py", line 489, in __call__
    result = self.forward(*input, **kwargs)
  File "/home/mocobt/.pyenv/versions/anaconda3-5.3.1/lib/python3.7/site-packages/torch/nn/modules/loss.py", line 504, in forward
    return F.binary_cross_entropy(input, target, weight=self.weight, reduction=self.reduction)
  File "/home/mocobt/.pyenv/versions/anaconda3-5.3.1/lib/python3.7/site-packages/torch/nn/functional.py", line 2027, in binary_cross_entropy
    input, target, weight, reduction_enum)
RuntimeError: reduce failed to synchronize: device-side assert triggered
