[INFO] 2019-01-07 23:50:39,522 >>	[START]  Processor.process_train()
[INFO] 2019-01-07 23:50:39,524 >>	[START]  FeatureExtractor.extract()
[INFO] 2019-01-07 23:50:40,452 >>	[FINISH] FeatureExtractor.extract(): [elapsed_time] >> 00:00:00
[ERROR] 2019-01-07 23:50:40,452 >>	Unexpected Exception Occurred.
Traceback (most recent call last):
  File "src/main.py", line 18, in <module>
    main(get_option())
  File "src/main.py", line 10, in main
    ProcessorFactory.process(args)
  File "/home/icebee/project/Malware/src/processor_factory.py", line 32, in process
    validity, predict = processor.process()
  File "/home/icebee/project/Malware/src/processor.py", line 26, in process
    validity = self.__process_train()
  File "/home/icebee/project/Malware/src/save_log.py", line 83, in wrapper
    result = func(*args, **kargs)
  File "/home/icebee/project/Malware/src/processor.py", line 43, in __process_train
    assert False
AssertionError
