[INFO] 2019-02-26 00:38:48,032 >>	Classifier Type: LGBM
[INFO] 2019-02-26 00:38:48,033 >>	Input Path: /Users/berry/Kaggle/malware/data/subset/min
[INFO] 2019-02-26 00:38:48,033 >>	--------------------------------
[INFO] 2019-02-26 00:38:48,034 >>	[START]  Processor.preprocess()
[INFO] 2019-02-26 00:38:48,035 >>	[START]  FeatureExtractor.extract()
[ERROR] 2019-02-26 00:38:49,244 >>	Unexpected Exception Occurred.
joblib.externals.loky.process_executor._RemoteTraceback: 
"""
Traceback (most recent call last):
  File "/Users/berry/.pyenv/versions/anaconda3-5.3.1/lib/python3.7/site-packages/joblib/externals/loky/process_executor.py", line 418, in _process_worker
    r = call_item()
  File "/Users/berry/.pyenv/versions/anaconda3-5.3.1/lib/python3.7/site-packages/joblib/externals/loky/process_executor.py", line 272, in __call__
    return self.fn(*self.args, **self.kwargs)
  File "/Users/berry/.pyenv/versions/anaconda3-5.3.1/lib/python3.7/site-packages/joblib/_parallel_backends.py", line 567, in __call__
    return self.func(*args, **kwargs)
  File "/Users/berry/.pyenv/versions/anaconda3-5.3.1/lib/python3.7/site-packages/joblib/parallel.py", line 225, in __call__
    for func, args, kwargs in self.items]
  File "/Users/berry/.pyenv/versions/anaconda3-5.3.1/lib/python3.7/site-packages/joblib/parallel.py", line 225, in <listcomp>
    for func, args, kwargs in self.items]
  File "/Users/berry/Kaggle/malware/features/base_feature.py", line 58, in calcFratures
    new_feature_df = eval(formula[0], locals())
  File "<string>", line 1, in <module>
  File "/Users/berry/Kaggle/malware/features/Kernel01.py", line 290, in is_converted_with_smart_screen
    assert False
AssertionError
"""

The above exception was the direct cause of the following exception:

Traceback (most recent call last):
  File "src/main.py", line 23, in <module>
    main(get_option())
  File "src/main.py", line 14, in main
    ProcessorFactory.process(args)
  File "/Users/berry/Kaggle/malware/src/processor_factory.py", line 39, in process
    validity, predict = processor.process()
  File "/Users/berry/Kaggle/malware/src/processor.py", line 41, in process
    feature_names = self.__preprocess()
  File "/Users/berry/Kaggle/malware/src/save_log.py", line 112, in wrapper
    result = func(*args, **kargs)
  File "/Users/berry/Kaggle/malware/src/processor.py", line 51, in __preprocess
    feature_extractor.extract(part="train", valid_dir=valid_dir)
  File "/Users/berry/Kaggle/malware/src/save_log.py", line 112, in wrapper
    result = func(*args, **kargs)
  File "/Users/berry/Kaggle/malware/src/feature_extractor.py", line 38, in extract
    feature_dict[group] = group_feature_instance.extract()
  File "/Users/berry/Kaggle/malware/features/Kernel01.py", line 38, in extract
    return super().extract()
  File "/Users/berry/Kaggle/malware/features/base_feature.py", line 110, in extract
    new_features_list = Parallel(n_jobs=get_njobs())([delayed(calcFratures)(name, formula) for name, formula in needCalculationFeatures.items()])
  File "/Users/berry/.pyenv/versions/anaconda3-5.3.1/lib/python3.7/site-packages/joblib/parallel.py", line 930, in __call__
    self.retrieve()
  File "/Users/berry/.pyenv/versions/anaconda3-5.3.1/lib/python3.7/site-packages/joblib/parallel.py", line 833, in retrieve
    self._output.extend(job.get(timeout=self.timeout))
  File "/Users/berry/.pyenv/versions/anaconda3-5.3.1/lib/python3.7/site-packages/joblib/_parallel_backends.py", line 521, in wrap_future_result
    return future.result(timeout=timeout)
  File "/Users/berry/.pyenv/versions/anaconda3-5.3.1/lib/python3.7/concurrent/futures/_base.py", line 432, in result
    return self.__get_result()
  File "/Users/berry/.pyenv/versions/anaconda3-5.3.1/lib/python3.7/concurrent/futures/_base.py", line 384, in __get_result
    raise self._exception
AssertionError
