[INFO] 2019-03-06 17:28:51,438 >>	Classifier Type: LGBM
[INFO] 2019-03-06 17:28:51,791 >>	Input Path: /home/berry/Malware/data/subset/lgbm_adv
[INFO] 2019-03-06 17:28:52,137 >>	--------------------------------
[INFO] 2019-03-06 17:28:52,490 >>	[START]  Processor.preprocess()
[INFO] 2019-03-06 17:28:52,847 >>	[START]  FeatureExtractor.extract()
[ERROR] 2019-03-06 18:20:57,478 >>	Unexpected Exception Occurred.
joblib.externals.loky.process_executor._RemoteTraceback: 
"""
Traceback (most recent call last):
  File "/home/berry/.pyenv/versions/3.6.6/lib/python3.6/site-packages/joblib/externals/loky/backend/queues.py", line 156, in _feed
    send_bytes(obj_)
  File "/home/berry/.pyenv/versions/3.6.6/lib/python3.6/multiprocessing/connection.py", line 200, in send_bytes
    self._send_bytes(m[offset:offset + size])
  File "/home/berry/.pyenv/versions/3.6.6/lib/python3.6/multiprocessing/connection.py", line 393, in _send_bytes
    header = struct.pack("!i", n)
struct.error: 'i' format requires -2147483648 <= number <= 2147483647
"""

The above exception was the direct cause of the following exception:

Traceback (most recent call last):
  File "src/main.py", line 23, in <module>
    main(get_option())
  File "src/main.py", line 14, in main
    ProcessorFactory.process(args)
  File "/home/berry/Malware/src/processor_factory.py", line 39, in process
    validity, predict = processor.process()
  File "/home/berry/Malware/src/processor.py", line 41, in process
    feature_names = self.__preprocess()
  File "/home/berry/Malware/src/save_log.py", line 112, in wrapper
    result = func(*args, **kargs)
  File "/home/berry/Malware/src/processor.py", line 51, in __preprocess
    feature_extractor.extract(part="train", valid_dir=valid_dir)
  File "/home/berry/Malware/src/save_log.py", line 112, in wrapper
    result = func(*args, **kargs)
  File "/home/berry/Malware/src/feature_extractor.py", line 36, in extract
    feature_dict[group] = group_feature_instance.extract()
  File "/home/berry/Malware/features/Categorical.py", line 67, in extract
    return super().extract()
  File "/home/berry/Malware/features/base_feature.py", line 97, in extract
    [delayed(calcFratures)(feature_name, feature_params) for feature_name, feature_params in needCalculationFeatures.items()])
  File "/home/berry/.pyenv/versions/3.6.6/lib/python3.6/site-packages/joblib/parallel.py", line 934, in __call__
    self.retrieve()
  File "/home/berry/.pyenv/versions/3.6.6/lib/python3.6/site-packages/joblib/parallel.py", line 833, in retrieve
    self._output.extend(job.get(timeout=self.timeout))
  File "/home/berry/.pyenv/versions/3.6.6/lib/python3.6/site-packages/joblib/_parallel_backends.py", line 521, in wrap_future_result
    return future.result(timeout=timeout)
  File "/home/berry/.pyenv/versions/3.6.6/lib/python3.6/concurrent/futures/_base.py", line 432, in result
    return self.__get_result()
  File "/home/berry/.pyenv/versions/3.6.6/lib/python3.6/concurrent/futures/_base.py", line 384, in __get_result
    raise self._exception
RuntimeError: The task could not be sent to the workers as it is too large for `send_bytes`.
